Workbook

Sheet TASK note
A6: Task
A8: 1 | B8: In the services table find people who we can count as ‘new’ by identifying those who commenced long term support as their first service during the year 2023-24
A10: 2 | B10: How many new starts were there per month, by type?
A12: 3 | B12: How many have autism?
A14: 4 | B14: By reference to the assessments completed table, calculate the median calendar days from assessment to long term support for new people
A16: 5 | B16: Present your results in a useful visual or visuals
A18: 6 | B18: What are the limitations of these data and what other areas would you consider useful to follow up?
A21: Notes
A22: The reporting year runs from 1st April to 31st March
A23: All data are fictional
G29: .

Sheet Raw Data 1
A1: Service ID | B1: Person ID | C1: Service Description | D1: Service Class | E1: Start Date | F1: End Date | G1: Service Provider
A2: 1 | B2: 1971 | C2: Personal Budget | D2: Long Term | E2: 44840 | F2: 44916 | G2: Green Ltd
A3: 2 | B3: 3823 | C3: Personal Budget | D3: Long Term | E3: 44832 | F3: 45114 | G3: Wells, Levy and Martin
A4: 3 | B4: 2820 | C4: Personal Budget | D4: Long Term | E4: 45057 | G4: Wood Group
A5: 4 | B5: 903 | C5: Equipment | D5: Low level | E5: 44765 | F5: 44953 | G5: Flores-Jones
A6: 5 | B6: 365 | C6: Personal Budget | D6: Long Term | E6: 43959 | F6: 44805 | G6: Byrd, Bradford and Jacobs
A7: 6 | B7: 4259 | C7: Nursing Home | D7: Long Term | E7: 44693 | F7: 45440 | G7: Sanders-Moore
A8: 7 | B8: 3120 | C8: Nursing Home | D8: Long Term | E8: 44739 | G8: Montgomery, Lee and Anderson
A9: 8 | B9: 2559 | C9: Residential Home | D9: Long Term | E9: 44731 | F9: 45208 | G9: Wilson, Hernandez and Allen
A10: 9 | B10: 1864 | C10: Direct Payment | D10: Long Term | E10: 44941 | F10: 44969 | G10: Jones, Phillips and Singleton
A11: 10 | B11: 116 | C11: Personal Budget | D11: Long Term | E11: 44898 | G11: Mcguire and Sons
A12: 11 | B12: 2385 | C12: Personal Budget | D12: Long Term | E12: 44467 | F12: 44785 | G12: Parsons-Sexton
A13: 12 | B13: 4977 | C13: Homecare | D13: Long Term | E13: 44891 | F13: 45034 | G13: Martinez Ltd
A14: 13 | B14: 3936 | C14: Equipment | D14: Low level | E14: 45077 | F14: 45307 | G14: Brock LLC
A15: 14 | B15: 4936 | C15: Direct Payment | D15: Long Term | E15: 45096 | F15: 45271 | G15: Cox LLC
A16: 15 | B16: 2491 | C16: Residential Home | D16: Long Term | E16: 45211 | F16: 45362 | G16: White-Murphy
A17: 16 | B17: 943 | C17: Direct Payment | D17: Long Term | E17: 44878 | G17: York, Williams and Young
A18: 17 | B18: 1725 | C18: Personal Budget | D18: Long Term | E18: 45016 | F18: 45325 | G18: Rowe-Price
A19: 18 | B19: 2335 | C19: Homecare | D19: Long Term | E19: 44986 | G19: Dodson PLC
A20: 19 | B20: 2768 | C20: Equipment | D20: Low level | E20: 44629 | F20: 45342 | G20: Carey Ltd
A21: 20 | B21: 1138 | C21: Residential Home | D21: Long Term | E21: 45143 | G21: Lamb and Sons
A22: 21 | B22: 2528 | C22: Direct Payment | D22: Long Term | E22: 45308 | F22: 45365 | G22: Kramer, Byrd and Walker
A23: 22 | B23: 4118 | C23: Residential Home | D23: Long Term | E23: 43899 | F23: 44515 | G23: Holloway-Orr
A24: 23 | B24: 3421 | C24: Personal Budget | D24: Long Term | E24: 44530 | F24: 45404 | G24: Mcknight Inc
A25: 24 | B25: 4779 | C25: Residential Home | D25: Long Term | E25: 44187 | F25: 45254 | G25: Rogers, Nichols and Huerta
A26: 25 | B26: 3907 | C26: Homecare | D26: Long Term | E26: 45367 | F26: 45528 | G26: Thornton-Martin
A27: 26 | B27: 3638 | C27: Residential Home | D27: Long Term | E27: 44325 | G27: Vasquez-Thompson
A28: 27 | B28: 2954 | C28: Nursing Home | D28: Long Term | E28: 44221 | G28: Sims-Cohen
A29: 28 | B29: 2368 | C29: Homecare | D29: Long Term | E29: 45289 | F29: 45384 | G29: Williams, Abbott and Goodwin
A30: 29 | B30: 4222 | C30: Direct Payment | D30: Short Term | E30: 45529 | F30: 45532 | G30: Mercado LLC
A31: 30 | B31: 277 | C31: Equipment | D31: Low level | E31: 44200 | F31: 44389 | G31: Smith-Guerrero
A32: 31 | B32: 2000 | C32: Equipment | D32: Low level | E32: 44085 | F32: 44304 | G32: Moore-Carlson
A33: 32 | B33: 1228 | C33: Personal Budget | D33: Long Term | E33: 45445 | F33: 45513 | G33: Navarro Group
A34: 33 | B34: 3753 | C34: Personal Budget | D34: Long Term | E34: 44365 | F34: 44992 | G34: Williams Group
A35: 34 | B35: 3736 | C35: Nursing Home | D35: Long Term | E35: 44755 | F35: 44997 | G35: Wright-Tucker
A36: 35 | B36: 696 | C36: Direct Payment | D36: Long Term | E36: 44177 | G36: Bautista Ltd
A37: 36 | B37: 1310 | C37: Equipment | D37: Low level | E37: 45112 | F37: 45214 | G37: Harper Group
A38: 37 | B38: 4153 | C38: Equipment | D38: Low level | E38: 44344 | F38: 44625 | G38: Bennett, Campos and Sanchez
A39: 38 | B39: 3235 | C39: Equipment | D39: Low level | E39: 45290 | F39: 45445 | G39: Perez-Cervantes
A40: 39 | B40: 4115 | C40: Equipment | D40: Low level | E40: 44939 | G40: Griffith PLC
...

Sheet Raw Data 2
A1: Person ID | B1: Event | C1: Assessment start | D1: Assessment end
A2: 1687 | B2: Assessment | C2: 45017 | D2: 45023
A3: 2116 | B3: Assessment | C3: 45017 | D3: 45022
A4: 2820 | B4: Assessment | C4: 45017 | D4: 45022
A5: 3514 | B5: Assessment | C5: 45017 | D5: 45022
A6: 3730 | B6: Assessment | C6: 45017 | D6: 45023
A7: 508 | B7: Assessment | C7: 45018 | D7: 45023
A8: 517 | B8: Assessment | C8: 45018 | D8: 45023
A9: 4209 | B9: Assessment | C9: 45019 | D9: 45025
A10: 2549 | B10: Assessment | C10: 45020 | D10: 45025
A11: 2750 | B11: Assessment | C11: 45020 | D11: 45025
A12: 446 | B12: Assessment | C12: 45021 | D12: 45026
A13: 2557 | B13: Assessment | C13: 45021 | D13: 45026
... A1089: 787 | B1089: Assessment | C1089: 45527 | D1089: 45537

Sheet Raw Data 3
A1: Person ID | B1: Gender | C1: Health condition | D1: Age band | E1: Accommodation status
A2: 1 | B2: Male | D2: 65+ | E2: Tenant: Private landlord
A3: 2 | B3: Female | D3: 18-64 | E3: Tenant: Private landlord
A4: 3 | B4: Female | D4: 18-64 | E4: Unknown
A5: 4 | B5: Male | D5: 18-64 | E5: Tenant: Private landlord
A6: 5 | B6: Male | D6: 18-64 | E6: Registered care home
A7: 6 | B7: Female | D7: 65+ | E7: Tenant: Private landlord
A8: 7 | B8: Male | D8: 18-64 | E8: Tenant: Local authority or other social housing provider
A9: 8 | B9: Female | C9: Dementia | D9: 65+ | E9: Tenant: Private landlord
A10: 9 | B10: Male | D10: 65+ | E10: Tenant: Private landlord
A11: 10 | B11: Male | C11: ASD | D11: 18-64 | E11: Tenant: Private landlord
A12: 11 | B12: Male | D12: 18-64 | E12: Tenant: Private landlord
A13: 12 | B13: Male | D13: 18-64 | E13: Tenant: Private landlord
A14: 13 | B14: Male | C14: Autism | D14: 18-64 | E14: Registered care home
A15: 14 | B15: Male | D15: 65+ | E15: Unknown
A16: 15 | B16: Female | D16: 18-64 | E16: Tenant: Private landlord
A17: 16 | B17: Female | D17: 65+ | E17: Registered care home
A18: 17 | B18: Male | D18: 18-64 | E18: Registered care home
A19: 18 | B19: Male | D19: 18-64 | E19: Tenant: Private landlord
A20: 19 | B20: Female | D20: 65+ | E20: Tenant: Private landlord
A21: 20 | B21: Female | D21: 18-64 | E21: Unknown
A22: 21 | B22: Female | D22: 18-64 | E22: Registered care home
A23: 22 | B23: Male | D23: 18-64 | E23: Tenant: Private landlord
A24: 23 | B24: Male | D24: 18-64 | E24: Tenant: Private landlord
A25: 24 | B25: Female | D25: 18-64 | E25: Tenant: Private landlord
A26: 25 | B26: Male | D26: 65+ | E26: Tenant: Private landlord
... A29: 28 | B29: Female | D29: 65+ | E29: Tenant: Private landlord
A30: 29 | B30: Male | C30: Dementia | D30: 65+ | E30: Unknown
A31: 30 | B31: Female | D31: 18-64 | E31: Tenant: Private landlord
A32: 31 | B32: Female | D32: 18-64 | E32: Tenant: Local authority or other social housing provider
A33: 32 | B33: Male | C33: Autism | D33: 18-64 | E33: Tenant: Private landlord
A34: 33 | B34: Female | C34: Partial sight/sight impaired | D34: 18-64 | E34: Registered care home
A35: 34 | B35: Female | D35: 18-64 | E35: Tenant: Private landlord
A36: 35 | B36: Female | D36: 65+ | E36: Tenant: Private landlord
A37: 36 | B37: Female | D37: 65+ | E37: Tenant: Private landlord
A38: 37 | B38: Male | D38: 65+ | E38: Tenant: Private landlord
A39: 38 | B39: Female | D39: 18-64 | E39: Unknown
A40: 39 | B40: Male | D40: 18-64 | E40: Tenant: Private landlord
A41: 40 | B41: Female | D41: 65+ | E41: Tenant: Private landlord
A42: 41 | B42: Female | D42: 65+ | E42: Unknown
...

Sheet New services table 
A1: Service ID | B1: Person ID | C1: Service Description | D1: Service Class | E1: Start Date | F1: End Date | G1: Service Provider | H1: Earliest Service Date | I1: Is First Service | L1: New People: | M1: =SUBTOTAL(3,B:B) -> 2525
A2: 1 | B2: 1971 | C2: Personal Budget | D2: Long Term | E2: 44840 | F2: 44916 | G2: Green Ltd | H2: =_xlfn.MINIFS(E:E,B:B,B2) -> 44840 | I2: =IF(E2=H2,"Yes","No") -> Yes
A3: 2 | B3: 3823 | C3: Personal Budget | D3: Long Term | E3: 44832 | F3: 45114 | G3: Wells, Levy and Martin | H3: =_xlfn.MINIFS(E:E,B:B,B3) -> 44832 | I3: =IF(E3=H3,"Yes","No") -> Yes
A4: 3 | B4: 2820 | C4: Personal Budget | D4: Long Term | E4: 45057 | G4: Wood Group | H4: =_xlfn.MINIFS(E:E,B:B,B4) -> 45057 | I4: =IF(E4=H4,"Yes","No") -> Yes
A5: 4 | B5: 903 | C5: Equipment | D5: Low level | E5: 44765 | F5: 44953 | G5: Flores-Jones | H5: =_xlfn.MINIFS(E:E,B:B,B5) -> 44765 | I5: =IF(E5=H5,"Yes","No") -> Yes | J5: =SUBTOTAL(9,A5:I5) -> 0
A6: 5 | B6: 365 | C6: Personal Budget | D6: Long Term | E6: 43959 | F6: 44805 | G6: Byrd, Bradford and Jacobs | H6: =_xlfn.MINIFS(E:E,B:B,B6) -> 43959 | I6: =IF(E6=H6,"Yes","No") -> Yes
A7: 6 | B7: 4259 | C7: Nursing Home | D7: Long Term | E7: 44693 | F7: 45440 | G7: Sanders-Moore | H7: =_xlfn.MINIFS(E:E,B:B,B7) -> 44693 | I7: =IF(E7=H7,"Yes","No") -> Yes
A8: 7 | B8: 3120 | C8: Nursing Home | D8: Long Term | E8: 44739 | G8: Montgomery, Lee and Anderson | H8: =_xlfn.MINIFS(E:E,B:B,B8) -> 44739 | I8: =IF(E8=H8,"Yes","No") -> Yes
A9: 8 | B9: 2559 | C9: Residential Home | D9: Long Term | E9: 44731 | F9: 45208 | G9: Wilson, Hernandez and Allen | H9: =_xlfn.MINIFS(E:E,B:B,B9) -> 43725 | I9: =IF(E9=H9,"Yes","No") -> No | J9: =SUBTOTAL(9,A9:I9) -> 0
A10: 9 | B10: 1864 | C10: Direct Payment | D10: Long Term | E10: 44941 | F10: 44969 | G10: Jones, Phillips and Singleton | H10: =_xlfn.MINIFS(E:E,B:B,B10) -> 44941 | I10: =IF(E10=H10,"Yes","No") -> Yes
A11: 10 | B11: 116 | C11: Personal Budget | D11: Long Term | E11: 44898 | G11: Mcguire and Sons | H11: =_xlfn.MINIFS(E:E,B:B,B11) -> 43779 | I11: =IF(E11=H11,"Yes","No") -> No | J11: =SUBTOTAL(9,A11:I11) -> 0
A12: 11 | B12: 2385 | C12: Personal Budget | D12: Long Term | E12: 44467 | F12: 44785 | G12: Parsons-Sexton | H12: =_xlfn.MINIFS(E:E,B:B,B12) -> 44211 | I12: =IF(E12=H12,"Yes","No") -> No | J12: =SUBTOTAL(9,A12:I12) -> 0
A13: 12 | B13: 4977 | C13: Homecare | D13: Long Term | E13: 44891 | F13: 45034 | G13: Martinez Ltd | H13: =_xlfn.MINIFS(E:E,B:B,B13) -> 44523 | I13: =IF(E13=H13,"Yes","No") -> No | J13: =SUBTOTAL(9,A13:I13) -> 0
A14: 13 | B14: 3936 | C14: Equipment | D14: Low level | E14: 45077 | F14: 45307 | G14: Brock LLC | H14: =_xlfn.MINIFS(E:E,B:B,B14) -> 44225 | I14: =IF(E14=H14,"Yes","No") -> No | J14: =SUBTOTAL(9,A14:I14) -> 0
A15: 14 | B15: 4936 | C15: Direct Payment | D15: Long Term | E15: 45096 | F15: 45271 | G15: Cox LLC | H15: =_xlfn.MINIFS(E:E,B:B,B15) -> 44949 | I15: =IF(E15=H15,"Yes","No") -> No | J15: =SUBTOTAL(9,A15:I15) -> 0
A16: 15 | B16: 2491 | C16: Residential Home | D16: Long Term | E16: 45211 | F16: 45362 | G16: White-Murphy | H16: =_xlfn.MINIFS(E:E,B:B,B16) -> 45211 | I16: =IF(E16=H16,"Yes","No") -> Yes
A17: 16 | B17: 943 | C17: Direct Payment | D17: Long Term | E17: 44878 | G17: York, Williams and Young | H17: =_xlfn.MINIFS(E:E,B:B,B17) -> 44878 | I17: =IF(E17=H17,"Yes","No") -> Yes
A18: 17 | B18: 1725 | C18: Personal Budget | D18: Long Term | E18: 45016 | F18: 45325 | G18: Rowe-Price | H18: =_xlfn.MINIFS(E:E,B:B,B18) -> 44220 | I18: =IF(E18=H18,"Yes","No") -> No | J18: =SUBTOTAL(9,A18:I18) -> 0
A19: 18 | B19: 2335 | C19: Homecare | D19: Long Term | E19: 44986 | G19: Dodson PLC | H19: =_xlfn.MINIFS(E:E,B:B,B19) -> 44033 | I19: =IF(E19=H19,"Yes","No") -> No | J19: =SUBTOTAL(9,A19:I19) -> 0
A20: 19 | B20: 2768 | C20: Equipment | D20: Low level | E20: 44629 | F20: 45342 | G20: Carey Ltd | H20: =_xlfn.MINIFS(E:E,B:B,B20) -> 44629 | I20: =IF(E20=H20,"Yes","No") -> Yes | J20: =SUBTOTAL(9,A20:I20) -> 0
A21: 20 | B21: 1138 | C21: Residential Home | D21: Long Term | E21: 45143 | G21: Lamb and Sons | H21: =_xlfn.MINIFS(E:E,B:B,B21) -> 45143 | I21: =IF(E21=H21,"Yes","No") -> Yes
A22: 21 | B22: 2528 | C22: Direct Payment | D22: Long Term | E22: 45308 | F22: 45365 | G22: Kramer, Byrd and Walker | H22: =_xlfn.MINIFS(E:E,B:B,B22) -> 45308 | I22: =IF(E22=H22,"Yes","No") -> Yes
A23: 22 | B23: 4118 | C23: Residential Home | D23: Long Term | E23: 43899 | F23: 44515 | G23: Holloway-Orr | H23: =_xlfn.MINIFS(E:E,B:B,B23) -> 43899 | I23: =IF(E23=H23,"Yes","No") -> Yes
A24: 23 | B24: 3421 | C24: Personal Budget | D24: Long Term | E24: 44530 | F24: 45404 | G24: Mcknight Inc | H24: =_xlfn.MINIFS(E:E,B:B,B24) -> 44530 | I24: =IF(E24=H24,"Yes","No") -> Yes
A25: 24 | B25: 4779 | C25: Residential Home | D25: Long Term | E25: 44187 | F25: 45254 | G25: Rogers, Nichols and Huerta | H25: =_xlfn.MINIFS(E:E,B:B,B25) -> 44187 | I25: =IF(E25=H25,"Yes","No") -> Yes
A26: 25 | B26: 3907 | C26: Homecare | D26: Long Term | E26: 45367 | F26: 45528 | G26: Thornton-Martin | H26: =_xlfn.MINIFS(E:E,B:B,B26) -> 43834 | I26: =IF(E26=H26,"Yes","No") -> No | J26: =SUBTOTAL(9,A26:I26) -> 0
A27: 26 | B27: 3638 | C27: Residential Home | D27: Long Term | E27: 44325 | G27: Vasquez-Thompson | H27: =_xlfn.MINIFS(E:E,B:B,B27) -> 43841 | I27: =IF(E27=H27,"Yes","No") -> No | J27: =SUBTOTAL(9,A27:I27) -> 0
A28: 27 | B28: 2954 | C28: Nursing Home | D28: Long Term | E28: 44221 | G28: Sims-Cohen | H28: =_xlfn.MINIFS(E:E,B:B,B28) -> 44184 | I28: =IF(E28=H28,"Yes","No") -> No | J28: =SUBTOTAL(9,A28:I28) -> 0
A29: 28 | B29: 2368 | C29: Homecare | D29: Long Term | E29: 45289 | F29: 45384 | G29: Williams, Abbott and Goodwin | H29: =_xlfn.MINIFS(E:E,B:B,B29) -> 45289 | I29: =IF(E29=H29,"Yes","No") -> Yes
A30: 29 | B30: 4222 | C30: Direct Payment | D30: Short Term | E30: 45529 | F30: 45532 | G30: Mercado LLC | H30: =_xlfn.MINIFS(E:E,B:B,B30) -> 44849 | I30: =IF(E30=H30,"Yes","No") -> No | J30: =SUBTOTAL(9,A30:I30) -> 0
A31: 30 | B31: 277 | C31: Equipment | D31: Low level | E31: 44200 | F31: 44389 | G31: Smith-Guerrero | H31: =_xlfn.MINIFS(E:E,B:B,B31) -> 44200 | I31: =IF(E31=H31,"Yes","No") -> Yes | J31: =SUBTOTAL(9,A31:I31) -> 0
A32: 31 | B32: 2000 | C32: Equipment | D32: Low level | E32: 44085 | F32: 44304 | G32: Moore-Carlson | H32: =_xlfn.MINIFS(E:E,B:B,B32) -> 44085 | I32: =IF(E32=H32,"Yes","No") -> Yes | J32: =SUBTOTAL(9,A32:I32) -> 0
A33: 32 | B33: 1228 | C33: Personal Budget | D33: Long Term | E33: 45445 | F33: 45513 | G33: Navarro Group | H33: =_xlfn.MINIFS(E:E,B:B,B33) -> 45445 | I33: =IF(E33=H33,"Yes","No") -> Yes
A34: 33 | B34: 3753 | C34: Personal Budget | D34: Long Term | E34: 44365 | F34: 44992 | G34: Williams Group | H34: =_xlfn.MINIFS(E:E,B:B,B34) -> 44365 | I34: =IF(E34=H34,"Yes","No") -> Yes
A35: 34 | B35: 3736 | C35: Nursing Home | D35: Long Term | E35: 44755 | F35: 44997 | G35: Wright-Tucker | H35: =_xlfn.MINIFS(E:E,B:B,B35) -> 43980 | I35: =IF(E35=H35,"Yes","No") -> No | J35: =SUBTOTAL(9,A35:I35) -> 0
A36: 35 | B36: 696 | C36: Direct Payment | D36: Long Term | E36: 44177 | G36: Bautista Ltd | H36: =_xlfn.MINIFS(E:E,B:B,B36) -> 44177 | I36: =IF(E36=H36,"Yes","No") -> Yes
A37: 36 | B37: 1310 | C37: Equipment | D37: Low level | E37: 45112 | F37: 45214 | G37: Harper Group | H37: =_xlfn.MINIFS(E:E,B:B,B37) -> 45112 | I37: =IF(E37=H37,"Yes","No") -> Yes | J37: =SUBTOTAL(9,A37:I37) -> 0
A38: 37 | B38: 4153 | C38: Equipment | D38: Low level | E38: 44344 | F38: 44625 | G38: Bennett, Campos and Sanchez | H38: =_xlfn.MINIFS(E:E,B:B,B38) -> 44344 | I38: =IF(E38=H38,"Yes","No") -> Yes | J38: =SUBTOTAL(9,A38:I38) -> 0
A39: 38 | B39: 3235 | C39: Equipment | D39: Low level | E39: 45290 | F39: 45445 | G39: Perez-Cervantes | H39: =_xlfn.MINIFS(E:E,B:B,B39) -> 44575 | I39: =IF(E39=H39,"Yes","No") -> No | J39: =SUBTOTAL(9,A39:I39) -> 0
A40: 39 | B40: 4115 | C40: Equipment | D40: Low level | E40: 44939 | G40: Griffith PLC | H40: =_xlfn.MINIFS(E:E,B:B,B40) -> 44116 | I40: =IF(E40=H40,"Yes","No") -> No | J40: =SUBTOTAL(9,A40:I40) -> 0
...

Sheet New assessments completed
A1: Person ID | B1: Event | C1: Assessment start | D1: Assessment end | E1: Support Date
A2: 1687 | B2: Assessment | C2: 45017 | D2: 45023 | E2: =D2-C2 -> 6
A3: 2116 | B3: Assessment | C3: 45017 | D3: 45022 | E3: =D3-C3 -> 5
A4: 2820 | B4: Assessment | C4: 45017 | D4: 45022 | E4: =D4-C4 -> 5
A5: 3514 | B5: Assessment | C5: 45017 | D5: 45022 | E5: =D5-C5 -> 5
A6: 3730 | B6: Assessment | C6: 45017 | D6: 45023 | E6: =D6-C6 -> 6
A7: 508 | B7: Assessment | C7: 45018 | D7: 45023 | E7: =D7-C7 -> 5
A8: 517 | B8: Assessment | C8: 45018 | D8: 45023 | E8: =D8-C8 -> 5
A9: 4209 | B9: Assessment | C9: 45019 | D9: 45025 | E9: =D9-C9 -> 6
A10: 2549 | B10: Assessment | C10: 45020 | D10: 45025 | E10: =D10-C10 -> 5
A11: 2750 | B11: Assessment | C11: 45020 | D11: 45025 | E11: =D11-C11 -> 5
A12: 446 | B12: Assessment | C12: 45021 | D12: 45026 | E12: =D12-C12 -> 5
A13: 2557 | B13: Assessment | C13: 45021 | D13: 45026 | E13: =D13-C13 -> 5
... A1089: 787 | B1089: Assessment | C1089: 45527 | D1089: 45537 | E1089: =D1089-C1089 -> 10

Sheet New People Info
A1: Person ID | B1: Gender | C1: Health condition | D1: Age band | E1: Accommodation status | F1: Row Labels | G1: Sum of Person ID | I1: Person ID | J1: Gender | K1: Health Condition | L1: Age | M1: Accomodation Status
A2: 1 | B2: Male | D2: 65+ | E2: Tenant: Private landlord | F2: ASD | G2: 4312 | I2: {=_xlfn._xlws.FILTER(A2:E100, (C2:C100="Autism") + (C2:C100="ASD"), "No results found")} -> 10 | J2: Male | K2: ASD | L2: 18-64 | M2: Tenant: Private landlord
A3: 2 | B3: Female | D3: 18-64 | E3: Tenant: Private landlord | F3: 18-64 | G3: 4312 | I3: 13 | J3: Male | K3: Autism | L3: 18-64 | M3: Registered care home
A4: 3 | B4: Female | D4: 18-64 | E4: Unknown | F4: Female | G4: 2690 | I4: 32 | J4: Male | K4: Autism | L4: 18-64 | M4: Tenant: Private landlord
A5: 4 | B5: Male | D5: 18-64 | E5: Tenant: Private landlord | F5: Male | G5: 1622 | I5: 85 | J5: Male | K5: Autism | L5: 18-64 | M5: Settled mainstream housing with family or friends
A6: 5 | B6: Male | D6: 18-64 | E6: Registered care home | F6: Autism | G6: 19727
A7: 6 | B7: Female | D7: 65+ | E7: Tenant: Private landlord | F7: 18-64 | G7: 19178
A8: 7 | B8: Male | D8: 18-64 | E8: Tenant: Local authority or other social housing provider | F8: Female | G8: 7177
A9: 8 | B9: Female | C9: Dementia | D9: 65+ | E9: Tenant: Private landlord | F9: Male | G9: 12001
A10: 9 | B10: Male | D10: 65+ | E10: Tenant: Private landlord | F10: 65+ | G10: 549
A11: 10 | B11: Male | C11: ASD | D11: 18-64 | E11: Tenant: Private landlord | F11: Female | G11: 426
A12: 11 | B12: Male | D12: 18-64 | E12: Tenant: Private landlord | F12: Male | G12: 123
A13: 12 | B13: Male | D13: 18-64 | E13: Tenant: Private landlord | F13: Blind/severely sight impaired | G13: 15892
A14: 13 | B14: Male | C14: Autism | D14: 18-64 | E14: Registered care home | F14: 18-64 | G14: 5907
A15: 14 | B15: Male | D15: 65+ | E15: Unknown | F15: Female | G15: 5858
A16: 15 | B16: Female | D16: 18-64 | E16: Tenant: Private landlord | F16: Male | G16: 49
A17: 16 | B17: Female | D17: 65+ | E17: Registered care home | F17: 65+ | G17: 9985
A18: 17 | B18: Male | D18: 18-64 | E18: Registered care home | F18: Female | G18: 4996
A19: 18 | B19: Male | D19: 18-64 | E19: Tenant: Private landlord | F19: Male | G19: 4989
A20: 19 | B20: Female | D20: 65+ | E20: Tenant: Private landlord | F20: Dementia | G20: 15415
A21: 20 | B21: Female | D21: 18-64 | E21: Unknown | F21: 65+ | G21: 15415
A22: 21 | B22: Female | D22: 18-64 | E22: Registered care home | F22: Female | G22: 4994
A23: 22 | B23: Male | D23: 18-64 | E23: Tenant: Private landlord | F23: Male | G23: 10421
A24: 23 | B24: Male | D24: 18-64 | E24: Tenant: Private landlord | F24: Partial sight/sight impaired | G24: 8850
A25: 24 | B25: Female | D25: 18-64 | E25: Tenant: Private landlord | F25: 18-64 | G25: 33
A26: 25 | B26: Male | D26: 65+ | E26: Tenant: Private landlord | F26: Female | G26: 33
... A29: 28 | B29: Female | D29: 65+ | E29: Tenant: Private landlord | F29: Male | G29: 8641
A30: 29 | B30: Male | C30: Dementia | D30: 65+ | E30: Unknown | F30: Grand Total | G30: 64196
A31: 30 | B31: Female | D31: 18-64 | E31: Tenant: Private landlord
A32: 31 | B32: Female | D32: 18-64 | E32: Tenant: Local authority or other social housing provider
A33: 32 | B33: Male | C33: Autism | D33: 18-64 | E33: Tenant: Private landlord
A34: 33 | B34: Female | C34: Partial sight/sight impaired | D34: 18-64 | E34: Registered care home
A35: 34 | B35: Female | D35: 18-64 | E35: Tenant: Private landlord
A36: 35 | B36: Female | D36: 65+ | E36: Tenant: Private landlord
A37: 36 | B37: Female | D37: 65+ | E37: Tenant: Private landlord
A38: 37 | B38: Male | D38: 65+ | E38: Tenant: Private landlord
A39: 38 | B39: Female | D39: 18-64 | E39: Unknown
A40: 39 | B40: Male | D40: 18-64 | E40: Tenant: Private landlord
A41: 40 | B41: Female | D41: 65+ | E41: Tenant: Private landlord
A42: 41 | B42: Female | D42: 65+ | E42: Unknown
...

Sheet Dashboard 1
A1: New People
A2: Service ID | B2: Person ID | C2: Health Condition | D2: Service Description | E2: Service Class | F2: Start Date | G2: End Date | H2: Service Provider | I2: Earliest Service Date | J2: Is First Service | K2: Month Started | M2: New People: | N2: =SUBTOTAL(3,B:B) -> 3937 | P2: Row Labels | Q2: Sum of Person ID
A3: 1 | B3: 1971 | D3: Personal Budget | E3: Long Term | F3: 44840 | G3: 44916 | H3: Green Ltd | I3: =_xlfn.MINIFS(F:F,B:B,B3) -> 44840 | J3: =IF(F3=I3,"True","False") -> True | K3: =TEXT(F1,"mmm-yyyy") -> Jan-1900 | P3: Apr-2020 | Q3: 121260
A4: 2 | B4: 3823 | D4: Personal Budget | E4: Long Term | F4: 44832 | G4: 45114 | H4: Wells, Levy and Martin | I4: =_xlfn.MINIFS(F:F,B:B,B4) -> 44832 | J4: =IF(F4=I4,"True","False") -> True | K4: =TEXT(F2,"mmm-yyyy") -> Start Date | P4: Apr-2021 | Q4: 171766
A5: 3 | B5: 2820 | C5: =_xlfn.XLOOKUP(A3,'New People Info'!A:A,'New People Info'!C:C) -> 0 | D5: Personal Budget | E5: Long Term | F5: 45057 | H5: Wood Group | I5: =_xlfn.MINIFS(F:F,B:B,B5) -> 45057 | J5: =IF(F5=I5,"True","False") -> True | K5: =TEXT(F3,"mmm-yyyy") -> Oct-2022 | P5: Apr-2022 | Q5: 175667
A6: 4 | B6: 903 | D6: Equipment | E6: Low level | F6: 44765 | G6: 44953 | H6: Flores-Jones | I6: =_xlfn.MINIFS(F:F,B:B,B6) -> 44765 | J6: =IF(F6=I6,"Yes","No") -> Yes | P6: Apr-2023 | Q6: 203213
A7: 5 | B7: 365 | D7: Personal Budget | E7: Long Term | F7: 43959 | G7: 44805 | H7: Byrd, Bradford and Jacobs | I7: =_xlfn.MINIFS(F:F,B:B,B7) -> 43959 | J7: =IF(F7=I7,"True","False") -> True | K7: =TEXT(F5,"mmm-yyyy") -> May-2023 | P7: Apr-2024 | Q7: 136263
A8: 6 | B8: 4259 | D8: Nursing Home | E8: Long Term | F8: 44693 | G8: 45440 | H8: Sanders-Moore | I8: =_xlfn.MINIFS(F:F,B:B,B8) -> 44693 | J8: =IF(F8=I8,"True","False") -> True | K8: =TEXT(F6,"mmm-yyyy") -> Jul-2022 | P8: Aug-2019 | Q8: 13602
A9: 7 | B9: 3120 | D9: Nursing Home | E9: Long Term | F9: 44739 | H9: Montgomery, Lee and Anderson | I9: =_xlfn.MINIFS(F:F,B:B,B9) -> 44739 | J9: =IF(F9=I9,"True","False") -> True | K9: =TEXT(F7,"mmm-yyyy") -> May-2020 | P9: Aug-2020 | Q9: 216676
A10: 8 | B10: 2559 | D10: Residential Home | E10: Long Term | F10: 44731 | G10: 45208 | H10: Wilson, Hernandez and Allen | I10: =_xlfn.MINIFS(F:F,B:B,B10) -> 43725 | J10: =IF(F10=I10,"True","False") -> False | K10: =TEXT(F8,"mmm-yyyy") -> May-2022 | P10: Aug-2021 | Q10: 175939
A11: 9 | B11: 1864 | D11: Direct Payment | E11: Long Term | F11: 44941 | G11: 44969 | H11: Jones, Phillips and Singleton | I11: =_xlfn.MINIFS(F:F,B:B,B11) -> 44941 | J11: =IF(F11=I11,"True","False") -> True | K11: =TEXT(F9,"mmm-yyyy") -> Jun-2022 | P11: Aug-2022 | Q11: 147030
A12: 10 | B12: 116 | D12: Personal Budget | E12: Long Term | F12: 44898 | H12: Mcguire and Sons | I12: =_xlfn.MINIFS(F:F,B:B,B12) -> 43779 | J12: =IF(F12=I12,"True","False") -> False | K12: =TEXT(F10,"mmm-yyyy") -> Jun-2022 | P12: Aug-2023 | Q12: 176620
A13: 11 | B13: 2385 | D13: Personal Budget | E13: Long Term | F13: 44467 | G13: 44785 | H13: Parsons-Sexton | I13: =_xlfn.MINIFS(F:F,B:B,B13) -> 44211 | J13: =IF(F13=I13,"True","False") -> False | K13: =TEXT(F11,"mmm-yyyy") -> Jan-2023 | P13: Aug-2024 | Q13: 184465
A14: 12 | B14: 4977 | D14: Homecare | E14: Long Term | F14: 44891 | G14: 45034 | H14: Martinez Ltd | I14: =_xlfn.MINIFS(F:F,B:B,B14) -> 44523 | J14: =IF(F14=I14,"True","False") -> False | K14: =TEXT(F12,"mmm-yyyy") -> Dec-2022 | P14: Dec-2019 | Q14: 129272
A15: 13 | B15: 3936 | D15: Equipment | E15: Low level | F15: 45077 | G15: 45307 | H15: Brock LLC | I15: =_xlfn.MINIFS(F:F,B:B,B15) -> 44225 | J15: =IF(F15=I15,"Yes","No") -> No | P15: Dec-2020 | Q15: 199933
A16: 14 | B16: 4936 | C16: =_xlfn.XLOOKUP(A14,'New People Info'!A:A,'New People Info'!C:C) -> 0 | D16: Direct Payment | E16: Long Term | F16: 45096 | G16: 45271 | H16: Cox LLC | I16: =_xlfn.MINIFS(F:F,B:B,B16) -> 44949 | J16: =IF(F16=I16,"True","False") -> False | K16: =TEXT(F14,"mmm-yyyy") -> Nov-2022 | M16: Number of new people who have Autism | N16: =COUNTIF(C:C,"Autism") -> 3 | P16: Dec-2021 | Q16: 162050
A17: 15 | B17: 2491 | C17: =_xlfn.XLOOKUP(A15,'New People Info'!A:A,'New People Info'!C:C) -> Autism | D17: Residential Home | E17: Long Term | F17: 45211 | G17: 45362 | H17: White-Murphy | I17: =_xlfn.MINIFS(F:F,B:B,B17) -> 45211 | J17: =IF(F17=I17,"True","False") -> True | K17: =TEXT(F15,"mmm-yyyy") -> May-2023 | P17: Dec-2022 | Q17: 170066
A18: 16 | B18: 943 | D18: Direct Payment | E18: Long Term | F18: 44878 | H18: York, Williams and Young | I18: =_xlfn.MINIFS(F:F,B:B,B18) -> 44878 | J18: =IF(F18=I18,"True","False") -> True | K18: =TEXT(F16,"mmm-yyyy") -> Jun-2023 | P18: Dec-2023 | Q18: 168758
A19: 17 | B19: 1725 | D19: Personal Budget | E19: Long Term | F19: 45016 | G19: 45325 | H19: Rowe-Price | I19: =_xlfn.MINIFS(F:F,B:B,B19) -> 44220 | J19: =IF(F19=I19,"True","False") -> False | K19: =TEXT(F17,"mmm-yyyy") -> Oct-2023 | P19: Feb-2020 | Q19: 152848
A20: 18 | B20: 2335 | D20: Homecare | E20: Long Term | F20: 44986 | H20: Dodson PLC | I20: =_xlfn.MINIFS(F:F,B:B,B20) -> 44033 | J20: =IF(F20=I20,"True","False") -> False | K20: =TEXT(F18,"mmm-yyyy") -> Nov-2022 | P20: Feb-2021 | Q20: 192076
A21: 19 | B21: 2768 | D21: Equipment | E21: Low level | F21: 44629 | G21: 45342 | H21: Carey Ltd | I21: =_xlfn.MINIFS(F:F,B:B,B21) -> 44629 | J21: =IF(F21=I21,"Yes","No") -> Yes | P21: Feb-2022 | Q21: 156308
A22: 20 | B22: 1138 | C22: =_xlfn.XLOOKUP(A20,'New People Info'!A:A,'New People Info'!C:C) -> 0 | D22: Residential Home | E22: Long Term | F22: 45143 | H22: Lamb and Sons | I22: =_xlfn.MINIFS(F:F,B:B,B22) -> 45143 | J22: =IF(F22=I22,"True","False") -> True | K22: =TEXT(F20,"mmm-yyyy") -> Mar-2023 | P22: Feb-2023 | Q22: 134005
A23: 21 | B23: 2528 | C23: =_xlfn.XLOOKUP(A21,'New People Info'!A:A,'New People Info'!C:C) -> 0 | D23: Direct Payment | E23: Long Term | F23: 45308 | G23: 45365 | H23: Kramer, Byrd and Walker | I23: =_xlfn.MINIFS(F:F,B:B,B23) -> 45308 | J23: =IF(F23=I23,"True","False") -> True | K23: =TEXT(F21,"mmm-yyyy") -> Mar-2022 | P23: Feb-2024 | Q23: 136394
A24: 22 | B24: 4118 | D24: Residential Home | E24: Long Term | F24: 43899 | G24: 44515 | H24: Holloway-Orr | I24: =_xlfn.MINIFS(F:F,B:B,B24) -> 43899 | J24: =IF(F24=I24,"True","False") -> True | K24: =TEXT(F22,"mmm-yyyy") -> Aug-2023 | P24: Jan-1900 | Q24: 1971
A25: 23 | B25: 3421 | D25: Personal Budget | E25: Long Term | F25: 44530 | G25: 45404 | H25: Mcknight Inc | I25: =_xlfn.MINIFS(F:F,B:B,B25) -> 44530 | J25: =IF(F25=I25,"True","False") -> True | K25: =TEXT(F23,"mmm-yyyy") -> Jan-2024 | P25: Jan-2020 | Q25: 162206
A26: 24 | B26: 4779 | D26: Residential Home | E26: Long Term | F26: 44187 | G26: 45254 | H26: Rogers, Nichols and Huerta | I26: =_xlfn.MINIFS(F:F,B:B,B26) -> 44187 | J26: =IF(F26=I26,"True","False") -> True | K26: =TEXT(F24,"mmm-yyyy") -> Mar-2020 | P26: Jan-2021 | Q26: 185855
A27: 25 | B27: 3907 | C27: =_xlfn.XLOOKUP(A25,'New People Info'!A:A,'New People Info'!C:C) -> 0 | D27: Homecare | E27: Long Term | F27: 45367 | G27: 45528 | H27: Thornton-Martin | I27: =_xlfn.MINIFS(F:F,B:B,B27) -> 43834 | J27: =IF(F27=I27,"True","False") -> False | K27: =TEXT(F25,"mmm-yyyy") -> Nov-2021 | P27: Jan-2022 | Q27: 167895
A28: 26 | B28: 3638 | D28: Residential Home | E28: Long Term | F28: 44325 | H28: Vasquez-Thompson | I28: =_xlfn.MINIFS(F:F,B:B,B28) -> 43841 | J28: =IF(F28=I28,"True","False") -> False | K28: =TEXT(F26,"mmm-yyyy") -> Dec-2020 | P28: Jan-2023 | Q28: 150711
A29: 27 | B29: 2954 | D29: Nursing Home | E29: Long Term | F29: 44221 | H29: Sims-Cohen | I29: =_xlfn.MINIFS(F:F,B:B,B29) -> 44184 | J29: =IF(F29=I29,"True","False") -> False | K29: =TEXT(F27,"mmm-yyyy") -> Mar-2024 | P29: Jan-2024 | Q29: 143217
A30: 28 | B30: 2368 | C30: =_xlfn.XLOOKUP(A28,'New People Info'!A:A,'New People Info'!C:C) -> 0 | D30: Homecare | E30: Long Term | F30: 45289 | G30: 45384 | H30: Williams, Abbott and Goodwin | I30: =_xlfn.MINIFS(F:F,B:B,B30) -> 45289 | J30: =IF(F30=I30,"True","False") -> True | K30: =TEXT(F28,"mmm-yyyy") -> May-2021 | P30: Jul-2020 | Q30: 153189
A31: 29 | B31: 4222 | D31: Direct Payment | E31: Short Term | F31: 45529 | G31: 45532 | H31: Mercado LLC | I31: =_xlfn.MINIFS(F:F,B:B,B31) -> 44849 | J31: =IF(F31=I31,"Yes","No") -> No | P31: Jul-2021 | Q31: 177849
A32: 30 | B32: 277 | D32: Equipment | E32: Low level | F32: 44200 | G32: 44389 | H32: Smith-Guerrero | I32: =_xlfn.MINIFS(F:F,B:B,B32) -> 44200 | J32: =IF(F32=I32,"Yes","No") -> Yes | P32: Jul-2022 | Q32: 145055
A33: 31 | B33: 2000 | D33: Equipment | E33: Low level | F33: 44085 | G33: 44304 | H33: Moore-Carlson | I33: =_xlfn.MINIFS(F:F,B:B,B33) -> 44085 | J33: =IF(F33=I33,"Yes","No") -> Yes | P33: Jul-2023 | Q33: 152853
A34: 32 | B34: 1228 | D34: Personal Budget | E34: Long Term | F34: 45445 | G34: 45513 | H34: Navarro Group | I34: =_xlfn.MINIFS(F:F,B:B,B34) -> 45445 | J34: =IF(F34=I34,"True","False") -> True | K34: =TEXT(F32,"mmm-yyyy") -> Jan-2021 | P34: Jul-2024 | Q34: 184439
A35: 33 | B35: 3753 | D35: Personal Budget | E35: Long Term | F35: 44365 | G35: 44992 | H35: Williams Group | I35: =_xlfn.MINIFS(F:F,B:B,B35) -> 44365 | J35: =IF(F35=I35,"True","False") -> True | K35: =TEXT(F33,"mmm-yyyy") -> Sep-2020 | P35: Jun-2020 | Q35: 163370
A36: 34 | B36: 3736 | D36: Nursing Home | E36: Long Term | F36: 44755 | G36: 44997 | H36: Wright-Tucker | I36: =_xlfn.MINIFS(F:F,B:B,B36) -> 43980 | J36: =IF(F36=I36,"True","False") -> False | K36: =TEXT(F34,"mmm-yyyy") -> Jun-2024 | P36: Jun-2021 | Q36: 166129
A37: 35 | B37: 696 | D37: Direct Payment | E37: Long Term | F37: 44177 | H37: Bautista Ltd | I37: =_xlfn.MINIFS(F:F,B:B,B37) -> 44177 | J37: =IF(F37=I37,"True","False") -> True | K37: =TEXT(F35,"mmm-yyyy") -> Jun-2021 | P37: Jun-2022 | Q37: 188501
A38: 36 | B38: 1310 | D38: Equipment | E38: Low level | F38: 45112 | G38: 45214 | H38: Harper Group | I38: =_xlfn.MINIFS(F:F,B:B,B38) -> 45112 | J38: =IF(F38=I38,"Yes","No") -> Yes | P38: Jun-2023 | Q38: 160176
A39: 37 | B39: 4153 | D39: Equipment | E39: Low level | F39: 44344 | G39: 44625 | H39: Bennett, Campos and Sanchez | I39: =_xlfn.MINIFS(F:F,B:B,B39) -> 44344 | J39: =IF(F39=I39,"Yes","No") -> Yes | P39: Jun-2024 | Q39: 166040
A40: 38 | B40: 3235 | D40: Equipment | E40: Low level | F40: 45290 | G40: 45445 | H40: Perez-Cervantes | I40: =_xlfn.MINIFS(F:F,B:B,B40) -> 44575 | J40: =IF(F40=I40,"Yes","No") -> No | P40: Mar-2020 | Q40: 161757
...

Sheet Dashboard 2
A1: Number of People with Autism and the Median Calendar Days from Assessment to Long Term Calendar Days for New People
I4: Question 3
A25: Q4: Median Number of Calendar Days for New People:
A26: {=_xlfn.LET( _xlpm.svc_class, 'New services table '!$D$2:$D$5001, _xlpm.svc_first, 'New services table '!$I$2:$I$5001, _xlpm.svc_start, 'New services table '!$E$2:$E$5001, _xlpm.svc_person, 'New services table '!$B$2:$B$5001, _xlpm.assess_person, 'New assessments completed'!$A$2:$A$1089, _xlpm.assess_end, 'New assessments completed'!$D$2:$D$1089, _xlpm.year_start, DATE(2023,4,1), _xlpm.year_end, DATE(2024,3,31), _xlpm.is_new, (_xlpm.svc_class="Long Term") * ((_xlpm.svc_first="Yes") + (_xlpm.svc_first=TRUE)) * (_xlpm.svc_start>=_xlpm.year_start) * (_xlpm.svc_start<=_xlpm.year_end), _xlpm.days_diff, IF(_xlpm.is_new, _xlpm.svc_start - _xlfn.XLOOKUP(_xlpm.svc_person, _xlpm.assess_person, _xlpm.assess_end, NA()), NA()), MEDIAN(IF(ISNUMBER(_xlpm.days_diff), _xlpm.days_diff)) )} -> 28

Sheet Dashboard 3
A25: New People: | C25: 3937 | J25: Median Number of Calendar Days: | R25: {=_xlfn.LET( _xlpm.svc_class, 'New services table '!$D$2:$D$5001, _xlpm.svc_first, 'New services table '!$I$2:$I$5001, _xlpm.svc_start, 'New services table '!$E$2:$E$5001, _xlpm.svc_person, 'New services table '!$B$2:$B$5001, _xlpm.assess_person, 'New assessments completed'!$A$2:$A$1089, _xlpm.assess_end, 'New assessments completed'!$D$2:$D$1089, _xlpm.year_start, DATE(2023,4,1), _xlpm.year_end, DATE(2024,3,31), _xlpm.is_new, (_xlpm.svc_class="Long Term") * ((_xlpm.svc_first="Yes") + (_xlpm.svc_first=TRUE)) * (_xlpm.svc_start>=_xlpm.year_start) * (_xlpm.svc_start<=_xlpm.year_end), _xlpm.days_diff, IF(_xlpm.is_new, _xlpm.svc_start - _xlfn.XLOOKUP(_xlpm.svc_person, _xlpm.assess_person, _xlpm.assess_end, NA()), NA()), MEDIAN(IF(ISNUMBER(_xlpm.days_diff), _xlpm.days_diff)) )} -> 28
A28: Number of People Who Have Autism: | F28: 3

Sheet Insights
